Workbook

Sheet Transacciones
C2: REGISTRO DE TRANSACCIONES (MARZO 2026-1)
C4: Responsable(s) de la actualización | G4: Última actualización
C5: Lesly Guzmán | G5: 24/04/2026
C7: ACTIVIDAD O EVENTO | E7: LIBRO SIMPLIFICADO - version 180 DC PUCP | M7: OBSERVACIONES
B8: Ord. | C8: Fecha de registro | D8: Nombre de la Actividad | E8: Glosa | F8: Monto (S/.) | G8: Descripcion | H8: Fecha del Comprobante | I8: Tipo de Comprobante | J8: Codigo de Comprobante (Nº, Serie, etc.) | K8: Nombre / Razón Social | L8: RUC / DNI
B9: 0 | F9: =921.05 -> 921.05 | G9: SALDO ANTERIOR FEBRERO
B10: 1 | C10: 13/03/2026 | D10: Inventarios de equipo | E10: Gasto | F10: 50 | G10: Bienvenida — Polos y photochecks (inventario)
B11: 2 | C11: 13/03/2026 | D11: Inventarios de equipo | E11: Gasto | F11: 120 | G11: Bienvenida — Polos y photochecks (inventario)
B12: 3 | C12: 18/03/2026 | D12: Inventarios de equipo | E12: Gasto | F12: 120 | G12: Bienvenida — Polos y photochecks (inventario)
B13: 4 | C13: 23/03/2026 | D13: Membresía | E13: Ingreso | F13: 10 | G13: Ingreso por pago de fee
B14: 5 | C14: 23/03/2026 | D14: Membresía | E14: Ingreso | F14: 10 | G14: Ingreso por pago de fee
B15: 6 | C15: 23/03/2026 | D15: Membresía | E15: Ingreso | F15: 10 | G15: Ingreso por pago de fee
B16: 7 | C16: 23/03/2026 | D16: Membresía | E16: Ingreso | F16: 10 | G16: Ingreso por pago de fee
B17: 8 | C17: 23/03/2026 | D17: Membresía | E17: Ingreso | F17: 10 | G17: Ingreso por pago de fee
B18: 9 | C18: 23/03/2026 | D18: Membresía | E18: Ingreso | F18: 10 | G18: Ingreso por pago de fee
B19: 10 | C19: 23/03/2026 | D19: Membresía | E19: Ingreso | F19: 10 | G19: Ingreso por pago de fee
B20: 11 | C20: 23/03/2026 | D20: Membresía | E20: Ingreso | F20: 10 | G20: Ingreso por pago de fee
B21: 12 | C21: 23/03/2026 | D21: Membresía | E21: Ingreso | F21: 10 | G21: Ingreso por pago de fee
... B80: 71 | C80: 30/03/2026 | D80: Membresía | E80: Ingreso | F80: 10 | G80: Ingreso por pago de fee

Sheet Ingresos y Egresos
B2: Resumen | D2: Monto | F2: Notas
B3: SALDO INICIAL (en efectivo) | D3: =Transacciones!F9 -> 921.05
B4: Total Ingresos | D4: =D102 -> 640
B5: Total Inversiones | D5: =D32 -> 0
B6: Total Egresos | D6: =D25 -> 483.17
B7: SALDO FINAL (en efectivo) | D7: =D3+D4-D6 -> 1077.88
C9: Egresos
B10: Mes | C10: Rubro | D10: Monto | E10: Destino | F10: Observaciones
D11: =Transacciones!F10 -> 50
D12: =Transacciones!F11 -> 120
D13: =Transacciones!F12 -> 120
D14: =Transacciones!F34 -> 50
D15: =Transacciones!F35 -> 12
D16: =Transacciones!F36 -> 37.9
D17: =Transacciones!F37 -> 93.27
B25: Total EGRESOS | D25: =SUM(D11:D24) -> 483.17
C28: Inversiones | D28: Egresos por IME
B29: Mes | C29: Rubro | D29: Monto | E29: Destino | F29: Observaciones
D30: 0
D31: 0
B32: Total INVERSIONES | D32: =D30+D31 -> 0
C35: Ingresos
B36: Mes | C36: Rubro | D36: Monto | E36: Destino | F36: Observaciones
C37: =Transacciones!G13 -> Ingreso por pago de fee | D37: =Transacciones!F13 -> 10 | E37: General
C38: =Transacciones!G14 -> Ingreso por pago de fee | D38: =Transacciones!F14 -> 10 | E38: General
C39: =Transacciones!G15 -> Ingreso por pago de fee | D39: =Transacciones!F15 -> 10 | E39: General
C40: =Transacciones!G16 -> Ingreso por pago de fee | D40: =Transacciones!F16 -> 10 | E40: General
C41: =Transacciones!G17 -> Ingreso por pago de fee | D41: =Transacciones!F17 -> 10 | E41: General
C42: =Transacciones!G18 -> Ingreso por pago de fee | D42: =Transacciones!F18 -> 10 | E42: General
C43: =Transacciones!G19 -> Ingreso por pago de fee | D43: =Transacciones!F19 -> 10 | E43: General
C44: =Transacciones!G20 -> Ingreso por pago de fee | D44: =Transacciones!F20 -> 10 | E44: General
C45: =Transacciones!G21 -> Ingreso por pago de fee | D45: =Transacciones!F21 -> 10 | E45: General
C46: =Transacciones!G22 -> Ingreso por pago de fee | D46: =Transacciones!F22 -> 10 | E46: General
C47: =Transacciones!G23 -> Ingreso por pago de fee | D47: =Transacciones!F23 -> 10 | E47: General
C48: =Transacciones!G24 -> Ingreso por pago de fee | D48: =Transacciones!F24 -> 10 | E48: General
... C57: =Transacciones!G33 -> Ingreso por pago de fee | D57: =Transacciones!F33 -> 10 | E57: General
C58: =Transacciones!G38 -> Ingreso por pago de fee | D58: =Transacciones!F38 -> 10 | E58: General
C59: =Transacciones!G39 -> Ingreso por pago de fee | D59: =Transacciones!F39 -> 10 | E59: General
C60: =Transacciones!G40 -> Ingreso por pago de fee | D60: =Transacciones!F40 -> 10 | E60: General
C61: =Transacciones!G41 -> Ingreso por pago de fee | D61: =Transacciones!F41 -> 10 | E61: General
...

Sheet Caja y Bancos
B2: LIBRO CAJA Y BANCOS
B4: Responsable(s) de la actualización | F4: Última actualización
B5: Lesly Guzmán | F5: 24/04/2026
B8: Numero correlativo de registro | C8: Fecha | D8: Metodo de pago | E8: Descripcion de la operacion | F8: Nº de Transaccion Bancaria | G8: INGRESO | H8: SALIDA
B9: =Transacciones!B10 -> 1 | C9: =Transacciones!C10 -> 13/03/2026 | D9: Plin | E9: =Transacciones!E10 -> Gasto | H9: =Transacciones!F10 -> 50 | I9: =Transacciones!I10 | J9: =Transacciones!J10
B10: =Transacciones!B11 -> 2 | C10: =Transacciones!C11 -> 13/03/2026 | D10: Plin | E10: =Transacciones!E11 -> Gasto | H10: =Transacciones!F11 -> 120
B11: =Transacciones!B12 -> 3 | C11: =Transacciones!C12 -> 18/03/2026 | D11: Plin | E11: =Transacciones!E12 -> Gasto | H11: =Transacciones!F12 -> 120
B12: =Transacciones!B13 -> 4 | C12: =Transacciones!C13 -> 23/03/2026 | D12: Plin | E12: =Transacciones!E13 -> Ingreso | G12: =Transacciones!F13 -> 10
B13: =Transacciones!B14 -> 5 | C13: =Transacciones!C14 -> 23/03/2026 | D13: Plin | E13: =Transacciones!E14 -> Ingreso | G13: =Transacciones!F14 -> 10
B14: =Transacciones!B15 -> 6 | C14: =Transacciones!C15 -> 23/03/2026 | D14: Plin | E14: =Transacciones!E15 -> Ingreso | G14: =Transacciones!F15 -> 10
B15: =Transacciones!B16 -> 7 | C15: =Transacciones!C16 -> 23/03/2026 | D15: Plin | E15: =Transacciones!E16 -> Ingreso | G15: =Transacciones!F16 -> 10
B16: =Transacciones!B17 -> 8 | C16: =Transacciones!C17 -> 23/03/2026 | D16: Plin | E16: =Transacciones!E17 -> Ingreso | G16: =Transacciones!F17 -> 10
B17: =Transacciones!B18 -> 9 | C17: =Transacciones!C18 -> 23/03/2026 | D17: Plin | E17: =Transacciones!E18 -> Ingreso | G17: =Transacciones!F18 -> 10
B18: =Transacciones!B19 -> 10 | C18: =Transacciones!C19 -> 23/03/2026 | D18: Plin | E18: =Transacciones!E19 -> Ingreso | G18: =Transacciones!F19 -> 10
B19: =Transacciones!B20 -> 11 | C19: =Transacciones!C20 -> 23/03/2026 | D19: Plin | E19: =Transacciones!E20 -> Ingreso | G19: =Transacciones!F20 -> 10
B20: =Transacciones!B21 -> 12 | C20: =Transacciones!C21 -> 23/03/2026 | D20: Plin | E20: =Transacciones!E21 -> Ingreso | G20: =Transacciones!F21 -> 10
B21: =Transacciones!B22 -> 13 | C21: =Transacciones!C22 -> 23/03/2026 | D21: Plin | E21: =Transacciones!E22 -> Ingreso | G21: =Transacciones!F22 -> 10
B22: =Transacciones!B23 -> 14 | C22: =Transacciones!C23 -> 24/03/2026 | D22: Plin | E22: =Transacciones!E23 -> Ingreso | G22: =Transacciones!F23 -> 10
B23: =Transacciones!B24 -> 15 | C23: =Transacciones!C24 -> 24/03/2026 | D23: Plin | E23: =Transacciones!E24 -> Ingreso | G23: =Transacciones!F24 -> 10
... B32: =Transacciones!B33 -> 24 | C32: =Transacciones!C33 -> 24/03/2026 | D32: Plin | E32: =Transacciones!E33 -> Ingreso | G32: =Transacciones!F33 -> 10
B33: =Transacciones!B34 -> 25 | C33: =Transacciones!C34 -> 24/03/2026 | D33: Plin | E33: =Transacciones!E34 -> Gasto | H33: =Transacciones!F34 -> 50
B34: =Transacciones!B35 -> 26 | C34: =Transacciones!C35 -> 24/03/2026 | D34: Plin | E34: =Transacciones!E35 -> Gasto | H34: =Transacciones!F35 -> 12
B35: =Transacciones!B36 -> 27 | C35: =Transacciones!C36 -> 24/03/2026 | D35: Plin | E35: =Transacciones!E36 -> Gasto | H35: =Transacciones!F36 -> 37.9
B36: =Transacciones!B37 -> 28 | C36: =Transacciones!C37 -> 24/03/2026 | D36: Plin | E36: =Transacciones!E37 -> Gasto | H36: =Transacciones!F37 -> 93.27
B37: =Transacciones!B38 -> 29 | C37: =Transacciones!C38 -> 25/03/2026 | D37: Plin | E37: =Transacciones!E38 -> Ingreso | G37: =Transacciones!F38 -> 10
B38: =Transacciones!B39 -> 30 | C38: =Transacciones!C39 -> 25/03/2026 | D38: Plin | E38: =Transacciones!E39 -> Ingreso | G38: =Transacciones!F39 -> 10
B39: =Transacciones!B40 -> 31 | C39: =Transacciones!C40 -> 25/03/2026 | D39: Plin | E39: =Transacciones!E40 -> Ingreso | G39: =Transacciones!F40 -> 10
B40: =Transacciones!B41 -> 32 | C40: =Transacciones!C41 -> 25/03/2026 | D40: Plin | E40: =Transacciones!E41 -> Ingreso | G40: =Transacciones!F41 -> 10
B41: =Transacciones!B42 -> 33 | C41: =Transacciones!C42 -> 25/03/2026 | D41: Plin | E41: =Transacciones!E42 -> Ingreso | G41: =Transacciones!F42 -> 10
B42: =Transacciones!B43 -> 34 | C42: =Transacciones!C43 -> 25/03/2026 | D42: Plin | E42: =Transacciones!E43 -> Ingreso | G42: =Transacciones!F43 -> 10
B43: =Transacciones!B44 -> 35 | C43: =Transacciones!C44 -> 25/03/2026 | D43: Plin | E43: =Transacciones!E44 -> Ingreso | G43: =Transacciones!F44 -> 10
B44: =Transacciones!B45 -> 36 | C44: =Transacciones!C45 -> 25/03/2026 | D44: Plin | E44: =Transacciones!E45 -> Ingreso | G44: =Transacciones!F45 -> 10
B45: =Transacciones!B46 -> 37 | C45: =Transacciones!C46 -> 25/03/2026 | D45: Plin | E45: =Transacciones!E46 -> Ingreso | G45: =Transacciones!F46 -> 10
B46: =Transacciones!B47 -> 38 | C46: =Transacciones!C47 -> 25/03/2026 | D46: Plin | E46: =Transacciones!E47 -> Ingreso | G46: =Transacciones!F47 -> 10
B47: =Transacciones!B48 -> 39 | C47: =Transacciones!C48 -> 25/03/2026 | D47: Plin | E47: =Transacciones!E48 -> Ingreso | G47: =Transacciones!F48 -> 10
B48: =Transacciones!B49 -> 40 | C48: =Transacciones!C49 -> 25/03/2026 | D48: Plin | E48: =Transacciones!E49 -> Ingreso | G48: =Transacciones!F49 -> 10
... B79: =Transacciones!B80 -> 71 | C79: =Transacciones!C80 -> 30/03/2026 | D79: Plin | E79: =Transacciones!E80 -> Ingreso | G79: =Transacciones!F80 -> 10
G84: =SUM(G9:G83) -> 640 | H84: =SUM(H9:H83) -> 483.17
E85: Saldo anterior | G85: =Transacciones!F9 -> 921.05
E86: Saldo actual | G86: =G84-H84+G85 -> 1077.88
