Workbook

Sheet Transacciones
C2: REGISTRO DE TRANSACCIONES (ABRIL 2026-1)
C4: Responsable(s) de la actualización | G4: Última actualización
C5: Lesly Guzmán | G5: 30/04/2026
C7: ACTIVIDAD O EVENTO | E7: LIBRO SIMPLIFICADO - version 180 DC PUCP | M7: OBSERVACIONES
B8: Ord. | C8: Fecha de registro | D8: Nombre de la Actividad | E8: Glosa | F8: Monto (S/.) | G8: Descripcion | H8: Fecha del Comprobante | I8: Tipo de Comprobante | J8: Codigo de Comprobante (Nº, Serie, etc.) | K8: Nombre / Razón Social | L8: RUC / DNI
B9: 0 | F9: 1077.88 | G9: SALDO ANTERIOR MARZO
B10: 1 | C10: 46026 | D10: Membresía | F10: 10 | G10: Ingreso por pago de fee
B11: 2 | C11: 46026 | D11: Membresía | F11: 10 | G11: Ingreso por pago de fee
B12: 3 | C12: 46057 | D12: Membresía | F12: 10 | G12: Ingreso por pago de fee
B13: 4 | C13: 46207 | D13: Membresía | F13: 10 | G13: Ingreso por pago de fee
B14: 5 | C14: 46207 | D14: Membresía | F14: 10 | G14: Ingreso por pago de fee
B15: 6 | C15: 46238 | D15: Membresía | F15: 10 | G15: Ingreso por pago de fee
B16: 7 | C16: 46238 | D16: Membresía | F16: 10 | G16: Ingreso por pago de fee
B17: 8 | C17: 14/04/2026 | D17: ITF | F17: 0.05 | G17: Traslado Interbank a BCP
B18: 9 | C18: 16/04/2026 | D18: Capacitación | F18: 54.83 | G18: BCG capacitacion en la UP
B19: 10 | C19: 19/04/2026 | D19: Membresía | F19: 20 | G19: Ingreso por pago de 2 fee
B20: 11 | C20: 22/04/2026 | D20: Membresía | F20: 10 | G20: Ingreso por pago de fee
B21: 12 | C21: 25/04/2026 | D21: Integración | F21: 20 | G21: Reserva local pizza (1ra Integración) | K21: Yape Mario Mer
B22: 13 | C22: 27/04/2026 | D22: Membresía | F22: 10 | G22: Ingreso por pago de fee

Sheet Ingresos y Egresos
B2: Resumen | D2: Monto | F2: Notas
B3: SALDO INICIAL (en efectivo) | D3: =Transacciones!F9 -> 1077.88
B4: Total Ingresos | D4: =D108 -> 110
B5: Total Inversiones | D5: =D32 -> 0
B6: Total Egresos | D6: =D25 -> 74.88
B7: SALDO FINAL (en efectivo) | D7: =D3+D4-D6 -> 1113
C9: Egresos
B10: Mes | C10: Rubro | D10: Monto | E10: Destino | F10: Observaciones
B11: =Transacciones!C17 -> 14/04/2026 | C11: =Transacciones!D17 -> ITF | D11: =Transacciones!F17 -> 0.05
B12: =Transacciones!C18 -> 16/04/2026 | C12: =Transacciones!D18 -> Capacitación | D12: =Transacciones!F18 -> 54.83
B13: =Transacciones!C21 -> 25/04/2026 | C13: =Transacciones!D21 -> Integración | D13: =Transacciones!F21 -> 20
B25: Total EGRESOS | D25: =SUM(D11:D24) -> 74.88
C28: Inversiones | D28: Egresos por IME
B29: Mes | C29: Rubro | D29: Monto | E29: Destino | F29: Observaciones
D30: 0
D31: 0
B32: Total INVERSIONES | D32: =D30+D31 -> 0
C35: Ingresos
B36: Mes | C36: Rubro | D36: Monto | E36: Destino | F36: Observaciones
B37: =Transacciones!C10 -> 46026 | C37: =Transacciones!D10 -> Membresía | D37: =Transacciones!F10 -> 10 | E37: General
B38: =Transacciones!C11 -> 46026 | C38: =Transacciones!D11 -> Membresía | D38: =Transacciones!F11 -> 10 | E38: General
B39: =Transacciones!C12 -> 46057 | C39: =Transacciones!D12 -> Membresía | D39: =Transacciones!F12 -> 10 | E39: General
B40: =Transacciones!C13 -> 46207 | C40: =Transacciones!D13 -> Membresía | D40: =Transacciones!F13 -> 10 | E40: General
B41: =Transacciones!C14 -> 46207 | C41: =Transacciones!D14 -> Membresía | D41: =Transacciones!F14 -> 10 | E41: General
B42: =Transacciones!C15 -> 46238 | C42: =Transacciones!D15 -> Membresía | D42: =Transacciones!F15 -> 10 | E42: General
B43: =Transacciones!C16 -> 46238 | C43: =Transacciones!D16 -> Membresía | D43: =Transacciones!F16 -> 10 | E43: General
B44: =Transacciones!C19 -> 19/04/2026 | C44: =Transacciones!D19 -> Membresía | D44: =Transacciones!F19 -> 20 | E44: General
B45: =Transacciones!C20 -> 22/04/2026 | C45: =Transacciones!D20 -> Membresía | D45: =Transacciones!F20 -> 10 | E45: General
B46: =Transacciones!C22 -> 27/04/2026 | C46: =Transacciones!D22 -> Membresía | D46: =Transacciones!F22 -> 10 | E46: General
C97: =Transacciones!G70 | D97: =Transacciones!F70
C98: =Transacciones!G71 | D98: =Transacciones!F71
C99: =Transacciones!G72 | D99: =Transacciones!F72
C100: =Transacciones!G73
C101: =Transacciones!G74
C102: =Transacciones!G75
C103: =Transacciones!G76
C104: =Transacciones!G77
C105: =Transacciones!G78
C106: =Transacciones!G79
B108: Total INGRESOS | D108: =SUM(D37:D107) -> 110
...

Sheet Caja y Bancos
B2: LIBRO CAJA Y BANCOS
B4: Responsable(s) de la actualización | F4: Última actualización
B5: Lesly Guzmán | F5: 30/04/2026
B8: Numero correlativo de registro | C8: Fecha | D8: Metodo de pago | E8: Descripcion de la operacion | F8: Nº de Transaccion Bancaria | G8: INGRESO | H8: SALIDA
B9: =Transacciones!B10 -> 1 | C9: =Transacciones!C10 -> 46026 | E9: =Transacciones!G10 -> Ingreso por pago de fee | G9: =Transacciones!F10 -> 10
B10: =Transacciones!B11 -> 2 | C10: =Transacciones!C11 -> 46026 | D10: Plin | E10: =Transacciones!G11 -> Ingreso por pago de fee | G10: =Transacciones!F11 -> 10
B11: =Transacciones!B12 -> 3 | C11: =Transacciones!C12 -> 46057 | D11: Plin | E11: =Transacciones!G12 -> Ingreso por pago de fee | G11: =Transacciones!F12 -> 10
B12: =Transacciones!B13 -> 4 | C12: =Transacciones!C13 -> 46207 | D12: Plin | E12: =Transacciones!G13 -> Ingreso por pago de fee | G12: =Transacciones!F13 -> 10
B13: =Transacciones!B14 -> 5 | C13: =Transacciones!C14 -> 46207 | D13: Plin | E13: =Transacciones!G14 -> Ingreso por pago de fee | G13: =Transacciones!F14 -> 10
B14: =Transacciones!B15 -> 6 | C14: =Transacciones!C15 -> 46238 | D14: Plin | E14: =Transacciones!G15 -> Ingreso por pago de fee | G14: =Transacciones!F15 -> 10
B15: =Transacciones!B16 -> 7 | C15: =Transacciones!C16 -> 46238 | D15: Plin | E15: =Transacciones!G16 -> Ingreso por pago de fee | G15: =Transacciones!F16 -> 10
B16: =Transacciones!B17 -> 8 | C16: =Transacciones!C17 -> 14/04/2026 | D16: Plin | E16: =Transacciones!G17 -> Traslado Interbank a BCP | H16: =Transacciones!F17 -> 0.05
B17: =Transacciones!B18 -> 9 | C17: =Transacciones!C18 -> 16/04/2026 | E17: =Transacciones!G18 -> BCG capacitacion en la UP | H17: =Transacciones!F18 -> 54.83
B18: =Transacciones!B19 -> 10 | C18: =Transacciones!C19 -> 19/04/2026 | E18: =Transacciones!G19 -> Ingreso por pago de 2 fee | G18: =Transacciones!F19 -> 20
B19: =Transacciones!B20 -> 11 | C19: =Transacciones!C20 -> 22/04/2026 | E19: =Transacciones!G20 -> Ingreso por pago de fee | G19: =Transacciones!F20 -> 10
B20: =Transacciones!B21 -> 12 | C20: =Transacciones!C21 -> 25/04/2026 | E20: =Transacciones!G21 -> Reserva local pizza (1ra Integración) | H20: =Transacciones!F21 -> 20
B21: =Transacciones!B22 -> 13 | C21: =Transacciones!C22 -> 27/04/2026 | E21: =Transacciones!G22 -> Ingreso por pago de fee | G21: =Transacciones!F22 -> 10
B22: =Transacciones!B23 | C22: =Transacciones!C23 | E22: =Transacciones!G23
B23: =Transacciones!B24 | C23: =Transacciones!C24 | E23: =Transacciones!G24
B24: =Transacciones!B25 | C24: =Transacciones!C25 | E24: =Transacciones!G24
B25: =Transacciones!B26 | C25: =Transacciones!C26 | E25: =Transacciones!G25
B26: =Transacciones!B27 | C26: =Transacciones!C27 | E26: =Transacciones!G26
B27: =Transacciones!B28 | C27: =Transacciones!C28 | E27: =Transacciones!G27
B28: =Transacciones!B29 | C28: =Transacciones!C28 | E28: =Transacciones!G28
B29: =Transacciones!B30 | C29: =Transacciones!C29 | E29: =Transacciones!G29
B30: =Transacciones!B31 | C30: =Transacciones!C30 | E30: =Transacciones!G30
B31: =Transacciones!B32 | C31: =Transacciones!C31 | E31: =Transacciones!G31
B32: =Transacciones!B33 | C32: =Transacciones!C32 | E32: =Transacciones!G32
B33: =Transacciones!B34 | C33: =Transacciones!C33 | E33: =Transacciones!G33
B34: =Transacciones!B35 | C34: =Transacciones!C34 | E34: =Transacciones!G34
B35: =Transacciones!B36 | C35: =Transacciones!C35 | E35: =Transacciones!G35
B36: =Transacciones!B37 | C36: =Transacciones!C36 | E36: =Transacciones!G36
B37: =Transacciones!B38 | C37: =Transacciones!C37 | E37: =Transacciones!G37
B38: =Transacciones!B39 | C38: =Transacciones!C38 | E38: =Transacciones!G38
B39: =Transacciones!B40 | C39: =Transacciones!C39 | E39: =Transacciones!G39
... B69: =Transacciones!B70 | C69: =Transacciones!C69 | E69: =Transacciones!G69
C70: =Transacciones!C70 | E70: =Transacciones!G70
C71: =Transacciones!C71 | E71: =Transacciones!G71
C72: =Transacciones!C72 | E72: =Transacciones!G72
G82: =SUM(G9:G81) -> 110 | H82: =SUM(H9:H81) -> 74.88
...
